# file_indexer.py
The Source of the file belongs to "jiweiliew/file_indexer.py" - https://gist.github.com/jiweiliew/f845747dbc8f25ae260e3556d4e28110
I have updated the code due to the error after updating pandas to verions 1.4.0.
